Workbook
Name KOL_DB_Header: #REF!

Sheet Cost estimator
B2: Build template for KOL contract negociation.

Sheet Sheet22
B3: dokdoksoda@gmail.com
B5: deenise@deeniseglitz.com
B6: dewyeweat@gmail.com
B12: Aguchi.benson@gmail.com
B13: paulinamikielskaa@gmail.com
B17: stormscape88@gmail.com
B23: hellomegsandalex@gmail.com
B24: Szeyun.low@gmail.com
B25: partners@brenttimm.com
B26: caseycollab@gmail.com
B28: foodtravelexplores@hotmail.com
B29: dhnhatuyen@gmail.com
... B114: zevhu212224@gmail.com

Sheet n8n
A1: Username | B1: Social media type
A2: =IFERROR(__xludf.DUMMYFUNCTION("FILTER('KOL database'!$C$2:$C$869,'KOL database'!$J$2:$J$869<=0)"),"#REF!") -> #REF! | B2: =iferror(XLOOKUP(A2,'KOL database'!$C$2:$C$869,'KOL database'!$F$2:$F$869),"")
B3: =iferror(XLOOKUP(A3,'KOL database'!$C$2:$C$869,'KOL database'!$F$2:$F$869),"")
B4: =iferror(XLOOKUP(A4,'KOL database'!$C$2:$C$869,'KOL database'!$F$2:$F$869),"")
B5: =iferror(XLOOKUP(A5,'KOL database'!$C$2:$C$869,'KOL database'!$F$2:$F$869),"")
B6: =iferror(XLOOKUP(A6,'KOL database'!$C$2:$C$869,'KOL database'!$F$2:$F$869),"")
B7: =iferror(XLOOKUP(A7,'KOL database'!$C$2:$C$869,'KOL database'!$F$2:$F$869),"")
B8: =iferror(XLOOKUP(A8,'KOL database'!$C$2:$C$869,'KOL database'!$F$2:$F$869),"")
B9: =iferror(XLOOKUP(A9,'KOL database'!$C$2:$C$869,'KOL database'!$F$2:$F$869),"")
B10: =iferror(XLOOKUP(A10,'KOL database'!$C$2:$C$869,'KOL database'!$F$2:$F$869),"")
B11: =iferror(XLOOKUP(A11,'KOL database'!$C$2:$C$869,'KOL database'!$F$2:$F$869),"")
B12: =iferror(XLOOKUP(A12,'KOL database'!$C$2:$C$869,'KOL database'!$F$2:$F$869),"")
B13: =iferror(XLOOKUP(A13,'KOL database'!$C$2:$C$869,'KOL database'!$F$2:$F$869),"")
B14: =iferror(XLOOKUP(A14,'KOL database'!$C$2:$C$869,'KOL database'!$F$2:$F$869),"")
... B90: =iferror(XLOOKUP(A90,'KOL database'!$C$2:$C$869,'KOL database'!$F$2:$F$869),"")

Sheet Booking TH
B1: KOL_ID | C1: Username | D1: Followers | E1: Country | F1: Social media URL | G1: Restaurant name | H1: Restaurant ID | I1: Cuisine Type | J1: Package Type | K1: Package price | L1: Package Name | M1: Alergies | N1: Comments | O1: Fee per content | P1: Hotel required | Q1: Validation 1 | R1: Sales in charge | S1: Target Date | T1: Target time | U1: No people | V1: Sales Check | W1: Line_thread_id | X1: Booking ID | Y1: Target post date | Z1: Post details | AA1: Notes | AB1: index
B2: HH-LOIMU | C2: immikeyu | D2: 319003 | E2: Bangkok | G2: Vertigo TOO Banyan Tree | H2: {=XLOOKUP(G2,'Restaurant DB'!B:B,'Restaurant DB'!A:A)} -> 712 | I2: {=XLOOKUP(G2,'Restaurant DB'!B:B,'Restaurant DB'!N:N)} -> Fusion, International | J2: Party Pack | O2: 25000 | Q2: Approved | R2: {=XLOOKUP(G2,'Restaurant DB'!B:B,'Restaurant DB'!I:I)} -> ravi@hungryhub.com, naravadee.sw@banyantree.com, | S2: 45499 | T2: 0.72916667 | U2: 2 | V2: Validated | Z2: Check Later
B3: HH-LOIMU | C3: immikeyu | D3: 319003 | E3: Bangkok | G3: Jim Thompson, A Thai Restaurant | H3: {=XLOOKUP(G3,'Restaurant DB'!B:B,'Restaurant DB'!A:A)} -> 4195 | I3: {=XLOOKUP(G3,'Restaurant DB'!B:B,'Restaurant DB'!N:N)} -> Thai | J3: Party Pack | O3: 25000 | Q3: Approved | R3: {=XLOOKUP(G3,'Restaurant DB'!B:B,'Restaurant DB'!I:I)} -> ravi@hungryhub.com | S3: 45587 | T3: 0.75 | U3: 2 | V3: Validated | Z3: Check Later
B4: HH-LOALZ | C4: ali.al5baz | D4: 94511 | E4: {=XLOOKUP(G4,'Restaurant DB All'!$B$32:$B$5758,'Restaurant DB All'!$I$32:$I$5758)} -> Bangkok | F4: Instagram.com/ali.al5baz | G4: JHOL Coastal Indian Cuisine | H4: {=iferror(XLOOKUP(G4,'Restaurant DB'!B:B,'Restaurant DB'!A:A),".")} -> 4496 | I4: {=XLOOKUP(G4,'Restaurant DB'!B:B,'Restaurant DB'!N:N)} -> Indian | J4: Party Pack | K4: 2990 | L4: Sharing Set for 2 People | O4: 3351.46 | R4: {=XLOOKUP(G4,'Restaurant DB'!B:B,'Restaurant DB'!I:I)} -> ravi@hungryhub.com | S4: 45623 | T4: 0.75 | U4: 2 | V4: Validated | Z4: Check Later
B5: HH-LOALZ | C5: ali.al5baz | D5: 94511 | E5: {=XLOOKUP(G5,'Restaurant DB All'!$B$32:$B$5758,'Restaurant DB All'!$I$32:$I$5758)} -> Bangkok | F5: Instagram.com/ali.al5baz | G5: Jharokha by Indus | H5: {=iferror(XLOOKUP(G5,'Restaurant DB'!B:B,'Restaurant DB'!A:A),".")} -> 4652 | I5: {=XLOOKUP(G5,'Restaurant DB'!B:B,'Restaurant DB'!N:N)} -> Indian | J5: Party Pack | K5: 3000 | L5: Exclusive Dinner Sharing Set for 2 People | O5: 3351.46 | R5: {=XLOOKUP(G5,'Restaurant DB'!B:B,'Restaurant DB'!I:I)} -> ravi@hungryhub.com | S5: 45624 | T5: 0.75 | U5: 2 | V5: Validated | Z5: Check Later
B6: HH-LOALZ | C6: ali.al5baz | D6: 94511 | E6: {=XLOOKUP(G6,'Restaurant DB All'!$B$32:$B$5758,'Restaurant DB All'!$I$32:$I$5758)} -> Bangkok | F6: Instagram.com/ali.al5baz | G6: Florae at Valia Hotel Bangkok | H6: {=iferror(XLOOKUP(G6,'Restaurant DB'!B:B,'Restaurant DB'!A:A),".")} -> 4456 | I6: {=XLOOKUP(G6,'Restaurant DB'!B:B,'Restaurant DB'!N:N)} -> European, Indian, Fusion, Steakhouse | J6: Party Pack | K6: 2599 | L6: Romantic Dinner: 5-Course for 2 People | O6: 3351.46 | R6: {=XLOOKUP(G6,'Restaurant DB'!B:B,'Restaurant DB'!I:I)} -> bond@hungryhub.com | S6: 45641 | T6: 0.83333333 | U6: 2 | V6: Validated | Z6: Check Later
B7: HH-LOALZ | C7: ali.al5baz | D7: 94511 | E7: {=XLOOKUP(G7,'Restaurant DB All'!$B$32:$B$5758,'Restaurant DB All'!$I$32:$I$5758)} -> Bangkok | F7: Instagram.com/ali.al5baz | G7: Nuatair Samyan Mitrtown | H7: {=iferror(XLOOKUP(G7,'Restaurant DB'!B:B,'Restaurant DB'!A:A),".")} -> 4875 | I7: {=XLOOKUP(G7,'Restaurant DB'!B:B,'Restaurant DB'!N:N)} -> Thai, European | J7: All You Can Eat | K7: 999 | L7: Premium: Nuatair Buffet (Jan 1st, 2025 Onwards) | O7: 3351.46 | R7: {=XLOOKUP(G7,'Restaurant DB'!B:B,'Restaurant DB'!I:I)} -> earth@hungryhub.com | S7: 45659 | T7: 0.75 | U7: 2 | V7: Validated | Z7: Check Later
B8: HH-LOBAS | C8: bangkok.rooftops | D8: 182445 | E8: Bangkok | F8: instagram.com/bangkok.rooftops | G8: The Speakeasy Rooftop Bar Bangkok | H8: {=XLOOKUP(G8,'Restaurant DB'!B:B,'Restaurant DB'!A:A)} -> 5140 | I8: {=XLOOKUP(G8,'Restaurant DB'!B:B,'Restaurant DB'!N:N)} -> Fusion, International, American, European | J8: Party Pack | K8: 1190 | L8: 2 Dishes with 1 Alcoholic Beverage (6-8 P.M.) | N8: N/A | O8: 12371 | Q8: Approved | R8: {=XLOOKUP(G8,'Restaurant DB'!B:B,'Restaurant DB'!I:I)} -> ravi@hungryhub.com | S8: 45680 | T8: 0.79166667 | U8: 2 | V8: Booked | X8: 6888788 | Y8: 45699 | Z8: Check Later
B9: HH-LOBAS | C9: bangkok.rooftops | D9: 182445 | E9: Bangkok | F9: instagram.com/bangkok.rooftops | G9: Dark Waters Rooftop Bar & Riverside | H9: {=XLOOKUP(G9,'Restaurant DB'!B:B,'Restaurant DB'!A:A)} -> 4511 | I9: {=XLOOKUP(G9,'Restaurant DB'!B:B,'Restaurant DB'!N:N)} -> International, Fusion, Thai | J9: Party Pack | K9: 1190 | L9: 2 Dishes + Free Flow Alcohol & Soft Drinks | O9: 12371 | Q9: Approved | R9: {=XLOOKUP(G9,'Restaurant DB'!B:B,'Restaurant DB'!I:I)} -> bond@hungryhub.com | S9: 45685 | T9: 0.79166667 | U9: 2 | V9: Booked | X9: 6863186 | Y9: 45701 | Z9: Check Later
B10: HH-LOBAS | C10: bangkok.rooftops | D10: 182445 | E10: Bangkok | F10: instagram.com/bangkok.rooftops | G10: Cielo Sky Bar & Restaurant Rooftop | H10: {=XLOOKUP(G10,'Restaurant DB'!B:B,'Restaurant DB'!A:A)} -> 3934 | I10: {=XLOOKUP(G10,'Restaurant DB'!B:B,'Restaurant DB'!N:N)} -> Fusion, Italian, Thai | J10: Party Pack | K10: 1990 | L10: New: Sharing Set for 2 People | O10: 12371 | Q10: Approved | R10: {=XLOOKUP(G10,'Restaurant DB'!B:B,'Restaurant DB'!I:I)} -> sirirat@hungryhub.com | S10: 45687 | T10: 0.79166667 | U10: 2 | V10: Booked | X10: 6867847 | Y10: 45718 | Z10: Check Later
B11: HH-LOBAS | C11: bangkok.rooftops | D11: 182445 | E11: Bangkok | F11: instagram.com/bangkok.rooftops | G11: LUZ Bangkok Tapas Bar | H11: {=XLOOKUP(G11,'Restaurant DB'!B:B,'Restaurant DB'!A:A)} -> 4897 | I11: {=XLOOKUP(G11,'Restaurant DB'!B:B,'Restaurant DB'!N:N)} -> Spanish | J11: Party Pack | K11: 2390 | L11: LUZ Premium Sharing Set for 2 People | O11: 12371 | Q11: Approved | R11: {=XLOOKUP(G11,'Restaurant DB'!B:B,'Restaurant DB'!I:I)} -> sirirat@hungryhub.com | S11: 45688 | T11: 0.79166667 | U11: 2 | V11: Booked | X11: 6868290 | Y11: 45719 | Z11: Check Later
B12: HH-LOBAS | C12: bangkok.rooftops | D12: 182445 | E12: Bangkok | F12: instagram.com/bangkok.rooftops | G12: ThreeSixty Rooftop Bar at Millennium Hilton Bangkok | H12: {=XLOOKUP(G12,'Restaurant DB'!B:B,'Restaurant DB'!A:A)} -> 4471 | I12: {=XLOOKUP(G12,'Restaurant DB'!B:B,'Restaurant DB'!N:N)} -> International | J12: Party Pack | K12: 1999 | L12: Sharing Set for 2 People with 4 Alcohol Drink | O12: 12371 | Q12: Approved | R12: {=XLOOKUP(G12,'Restaurant DB'!B:B,'Restaurant DB'!I:I)} -> bond@hungryhub.com | S12: 45690 | T12: 0.79166667 | U12: 2 | V12: Booked | X12: 6917649 | Y12: 45700 | Z12: Check Later
B13: =XLOOKUP(C13,'KOL database'!$C$2:$C$869,'KOL database'!$B$2:$B$869) -> #REF! | C13: howtotravelfulltime | D13: 100047 | E13: {=XLOOKUP(G13,'Restaurant DB All'!$B$32:$B$5758,'Restaurant DB All'!$I$32:$I$5758)} -> Bangkok | G13: Butcher Factory by Bangkok Butcher | H13: {=XLOOKUP(G13,'Restaurant DB'!B:B,'Restaurant DB'!A:A)} -> 4178 | I13: {=XLOOKUP(G13,'Restaurant DB'!B:B,'Restaurant DB'!N:N)} -> Steakhouse, Italian, International, American, European | J13: All You Can Eat | K13: 1159 | L13: Dry Aged Buffet Steak | O13: 13500 | Q13: Approved | R13: {=XLOOKUP(G13,'Restaurant DB'!B:B,'Restaurant DB'!I:I)} -> earth@hungryhub.com | S13: 45703 | T13: 0.79166667 | Z13: Check Later
B14: =XLOOKUP(C14,'KOL database'!$C$2:$C$869,'KOL database'!$B$2:$B$869) -> #REF! | C14: eaterries | D14: 26326 | E14: Singapore | G14: Warm Up Cafe @ Mackenzie Road | H14: {=XLOOKUP(G14,'Restaurant DB'!B:B,'Restaurant DB'!A:A)} -> 5318 | I14: {=XLOOKUP(G14,'Restaurant DB'!B:B,'Restaurant DB'!N:N)} -> Thai | J14: Party Pack | K14: 69 | L14: Sharing Set for 2 People | O14: 5062.58 | Q14: Approved | R14: {=XLOOKUP(G14,'Restaurant DB'!B:B,'Restaurant DB'!I:I)} -> fred@hungryhub.com | S14: 45713 | T14: 0.77083333 | U14: 2 | V14: Booked | X14: 7186274 | Z14: Check Later
B15: HH-SGMEY | C15: melicacy | D15: 44191 | E15: {=XLOOKUP(G15,'Restaurant DB All'!$B$32:$B$5758,'Restaurant DB All'!$I$32:$I$5758)} -> Singapore | F15: Instagram.com/melicacy | G15: Forma | H15: {=iferror(XLOOKUP(G15,'Restaurant DB'!B:B,'Restaurant DB'!A:A),".")} -> 5345 | I15: {=XLOOKUP(G15,'Restaurant DB'!B:B,'Restaurant DB'!N:N)} -> Italian | J15: Party Pack | K15: 112 | L15: 3-COURSE WINTER SET DINNER | O15: 5062.58 | R15: {=XLOOKUP(G15,'Restaurant DB'!B:B,'Restaurant DB'!I:I)} -> fred@hungryhub.com | S15: 45713 | T15: 0.79166667 | U15: 2 | V15: Validated | Z15: Check Later
B16: HH-SGMEY | C16: melicacy | D16: 44191 | E16: {=XLOOKUP(G16,'Restaurant DB All'!$B$32:$B$5758,'Restaurant DB All'!$I$32:$I$5758)} -> Singapore | F16: Instagram.com/melicacy | G16: Wild Child Pizzette | H16: {=iferror(XLOOKUP(G16,'Restaurant DB'!B:B,'Restaurant DB'!A:A),".")} -> 5344 | I16: {=XLOOKUP(G16,'Restaurant DB'!B:B,'Restaurant DB'!N:N)} -> Italian | J16: Party Pack | K16: 151 | L16: Sharing Set for 2 People | O16: 5062.58 | R16: {=XLOOKUP(G16,'Restaurant DB'!B:B,'Restaurant DB'!I:I)} -> fred@hungryhub.com | S16: 45714 | T16: 0.79166667 | U16: 2 | V16: Validated | Z16: Check Later
B17: HH-LOALZ | C17: ali.al5baz | D17: 94511 | E17: {=XLOOKUP(G17,'Restaurant DB All'!$B$32:$B$5758,'Restaurant DB All'!$I$32:$I$5758)} -> Bangkok | F17: Instagram.com/ali.al5baz | G17: Copper Beyond Buffet Gaysorn Amarin (Hungry Hub) | H17: {=iferror(XLOOKUP(G17,'Restaurant DB'!B:B,'Restaurant DB'!A:A),".")} -> 4503 | I17: {=XLOOKUP(G17,'Restaurant DB'!B:B,'Restaurant DB'!N:N)} -> European, Fusion, International, Japanese, Thai | J17: All You Can Eat | K17: 2599 | L17: Hungry Hub Pack A - Select 1 Premium Menu | O17: 3351.46 | R17: {=XLOOKUP(G17,'Restaurant DB'!B:B,'Restaurant DB'!I:I)} -> surasit@hungryhub.com | S17: 45717 | T17: 0.8125 | U17: 2 | V17: Validated | Z17: Check Later
B18: HH-LOALZ | C18: ali.al5baz | D18: 94511 | E18: {=XLOOKUP(G18,'Restaurant DB All'!$B$32:$B$5758,'Restaurant DB All'!$I$32:$I$5758)} -> Bangkok | F18: Instagram.com/ali.al5baz | G18: Butcher Factory by Bangkok Butcher | H18: {=iferror(XLOOKUP(G18,'Restaurant DB'!B:B,'Restaurant DB'!A:A),".")} -> 4178 | I18: {=XLOOKUP(G18,'Restaurant DB'!B:B,'Restaurant DB'!N:N)} -> Steakhouse, Italian, International, American, European | J18: All You Can Eat | K18: 1399 | L18: Dry Aged Buffet Steak | O18: 3351.46 | R18: {=XLOOKUP(G18,'Restaurant DB'!B:B,'Restaurant DB'!I:I)} -> earth@hungryhub.com | S18: 45718 | T18: 0.79166667 | U18: 2 | V18: Validated | Z18: Check Later
B19: HH-LOALZ | C19: ali.al5baz | D19: 94511 | E19: {=XLOOKUP(G19,'Restaurant DB All'!$B$32:$B$5758,'Restaurant DB All'!$I$32:$I$5758)} -> Bangkok | F19: Instagram.com/ali.al5baz | G19: Mix Beef Club & Restaurant BKK | H19: {=iferror(XLOOKUP(G19,'Restaurant DB'!B:B,'Restaurant DB'!A:A),".")} -> 4912 | I19: {=XLOOKUP(G19,'Restaurant DB'!B:B,'Restaurant DB'!N:N)} -> Steakhouse, Chinese, Italian, International, Fusion, Thai, European, Thai Southern, Thai Northern | J19: Party Pack | K19: 2190 | L19: Sharing Set for 2 People | O19: 3351.46 | R19: {=XLOOKUP(G19,'Restaurant DB'!B:B,'Restaurant DB'!I:I)} -> bond@hungryhub.com | S19: 45720 | T19: 0.79166667 | U19: 2 | V19: Validated | Z19: Check Later
B20: HH-SGMEY | C20: melicacy | D20: 44191 | E20: {=XLOOKUP(G20,'Restaurant DB All'!$B$32:$B$5758,'Restaurant DB All'!$I$32:$I$5758)} -> Singapore | F20: Instagram.com/melicacy | G20: Mizuya Omakase | H20: {=iferror(XLOOKUP(G20,'Restaurant DB'!B:B,'Restaurant DB'!A:A),".")} -> 5362 | I20: {=XLOOKUP(G20,'Restaurant DB'!B:B,'Restaurant DB'!N:N)} -> Japanese | J20: Party Pack | K20: 155 | L20: Special x2 Omakase 7 Course With Free Flow Green Tea | O20: 5062.58 | R20: {=XLOOKUP(G20,'Restaurant DB'!B:B,'Restaurant DB'!I:I)} -> fred@hungryhub.com | S20: 45720 | T20: 0.79166667 | U20: 2 | V20: Validated | Z20: Check Later
B21: HH-LOALZ | C21: ali.al5baz | D21: 94511 | E21: {=XLOOKUP(G21,'Restaurant DB All'!$B$32:$B$5758,'Restaurant DB All'!$I$32:$I$5758)} -> Bangkok | F21: Instagram.com/ali.al5baz | G21: Mojjo Rooftop Lounge & Bar Skyview Hotel | H21: {=iferror(XLOOKUP(G21,'Restaurant DB'!B:B,'Restaurant DB'!A:A),".")} -> 643 | I21: {=XLOOKUP(G21,'Restaurant DB'!B:B,'Restaurant DB'!N:N)} -> Cuban, Fusion, Mexican, Peruvian | J21: Party Pack | K21: 999 | L21: 3 Dishes & Free Flow Non-Alc. Drinks (90 Mins) | O21: 3351.46 | R21: {=XLOOKUP(G21,'Restaurant DB'!B:B,'Restaurant DB'!I:I)} -> ravi@hungryhub.com | S21: 45721 | T21: 0.79166667 | U21: 2 | V21: Validated | Z21: Check Later
B22: HH-LOALZ | C22: ali.al5baz | D22: 94511 | E22: {=XLOOKUP(G22,'Restaurant DB All'!$B$32:$B$5758,'Restaurant DB All'!$I$32:$I$5758)} -> Bangkok | F22: Instagram.com/ali.al5baz | G22: The Seafood Cafe & Restaurant | H22: {=iferror(XLOOKUP(G22,'Restaurant DB'!B:B,'Restaurant DB'!A:A),".")} -> 1433 | I22: {=XLOOKUP(G22,'Restaurant DB'!B:B,'Restaurant DB'!N:N)} -> Thai, Chinese, International, Fusion | J22: All You Can Eat | K22: 1690 | L22: Premium Seafood Buffet + 1 Premium Jumbo River Prawn | O22: 3351.46 | R22: {=XLOOKUP(G22,'Restaurant DB'!B:B,'Restaurant DB'!I:I)} -> sirirat@hungryhub.com | S22: 45722 | T22: 0.79166667 | U22: 2 | V22: Validated | Z22: Check Later
B23: HH-LODAJ | C23: daddy.xj | D23: 126196 | E23: Bangkok | G23: NAMA Japanese and Seafood Buffet (Hungry Hub) | H23: {=XLOOKUP(G23,'Restaurant DB'!B:B,'Restaurant DB'!A:A)} -> 5149 | I23: {=XLOOKUP(G23,'Restaurant DB'!B:B,'Restaurant DB'!N:N)} -> Japanese | J23: All You Can Eat | K23: 1650 | L23: Premium Box 1 Set + Exclusive Menu + Buffet Line (Sat-Sun) | O23: 5000 | Q23: Approved | R23: {=XLOOKUP(G23,'Restaurant DB'!B:B,'Restaurant DB'!I:I)} -> earth@hungryhub.com | S23: 45724 | T23: 0.54166667 | U23: 2 (1 Adult, 1 kid) | V23: Validated | Z23: Check Later
B24: HH-LOTHI | C24: thara_koiii | D24: 95611 | E24: {=XLOOKUP(G24,'Restaurant DB All'!$B$32:$B$5758,'Restaurant DB All'!$I$32:$I$5758)} -> Singapore | F24: Instagram.com/thara_koiii | G24: Colony At The Ritz-Carlton, Millenia Singapore | H24: {=iferror(XLOOKUP(G24,'Restaurant DB'!B:B,'Restaurant DB'!A:A),".")} -> 5412 | I24: {=XLOOKUP(G24,'Restaurant DB'!B:B,'Restaurant DB'!N:N)} -> International, Singaporean | J24: All You Can Eat | K24: 89 | L24: Lunch Buffet (Mon-Fri) | O24: 1685.8391 | R24: {=XLOOKUP(G24,'Restaurant DB'!B:B,'Restaurant DB'!I:I)} -> fred@hungryhub.com | S24: 45726 | T24: 0.5 | U24: 2 | V24: Validated | Z24: Check Later
B25: =XLOOKUP(C25,'KOL database'!$C$2:$C$869,'KOL database'!$B$2:$B$869) -> #REF! | C25: eaterries | D25: 26326 | E25: Singapore | G25: Wild Child Pizzette | H25: {=XLOOKUP(G25,'Restaurant DB'!B:B,'Restaurant DB'!A:A)} -> 5344 | I25: {=XLOOKUP(G25,'Restaurant DB'!B:B,'Restaurant DB'!N:N)} -> Italian | J25: Party Pack | K25: 151 | L25: Sharing Set for 2 People | O25: 5062.58 | Q25: Approved | R25: {=XLOOKUP(G25,'Restaurant DB'!B:B,'Restaurant DB'!I:I)} -> fred@hungryhub.com | S25: 45731 | T25: 0.54166667 | U25: 2 | V25: Booked | X25: 7175926 | Z25: Check Later
B26: =XLOOKUP(C26,'KOL database'!$C$2:$C$869,'KOL database'!$B$2:$B$869) -> #REF! | C26: eaterries | D26: 26326 | E26: Singapore | G26: Fook Kin 福劲 | H26: {=XLOOKUP(G26,'Restaurant DB'!B:B,'Restaurant DB'!A:A)} -> 5376 | I26: {=XLOOKUP(G26,'Restaurant DB'!B:B,'Restaurant DB'!N:N)} -> Chinese, Singaporean | J26: Party Pack | K26: 76 | L26: Sharing Set for 2 People | O26: 5062.58 | Q26: Approved | R26: {=XLOOKUP(G26,'Restaurant DB'!B:B,'Restaurant DB'!I:I)} -> fred@hungryhub.com | S26: 45734 | T26: 0.79166667 | U26: 2 | V26: Booked | X26: 7344487 | Z26: Check Later
B27: =XLOOKUP(C27,'KOL database'!$C$2:$C$869,'KOL database'!$B$2:$B$869) -> #REF! | C27: sgadventurousduo | D27: 117433 | E27: {=XLOOKUP(G27,'Restaurant DB All'!$B$32:$B$5758,'Restaurant DB All'!$I$32:$I$5758)} -> Bangkok | G27: Kam's Roast Central World | H27: {=XLOOKUP(G27,'Restaurant DB'!B:B,'Restaurant DB'!A:A)} -> 5251 | I27: {=XLOOKUP(G27,'Restaurant DB'!B:B,'Restaurant DB'!N:N)} -> Chinese | J27: Party Pack | K27: 1190 | L27: Premium Set for 2 People | O27: 5905.4996 | Q27: Approved | R27: {=XLOOKUP(G27,'Restaurant DB'!B:B,'Restaurant DB'!I:I)} -> earth@hungryhub.com | S27: 45736 | T27: 0.79166667 | Z27: Check Later
B28: =XLOOKUP(C28,'KOL database'!$C$2:$C$869,'KOL database'!$B$2:$B$869) -> #REF! | C28: sgadventurousduo | D28: 117433 | E28: {=XLOOKUP(G28,'Restaurant DB All'!$B$32:$B$5758,'Restaurant DB All'!$I$32:$I$5758)} -> Bangkok | G28: Oishi Grand Siam Paragon | H28: {=XLOOKUP(G28,'Restaurant DB'!B:B,'Restaurant DB'!A:A)} -> 4039 | I28: {=XLOOKUP(G28,'Restaurant DB'!B:B,'Restaurant DB'!N:N)} -> European, Fusion, International, Japanese | J28: All You Can Eat | K28: 1119 | L28: Oishi Grand: Premium Buffet | O28: 5905.4996 | Q28: Approved | R28: {=XLOOKUP(G28,'Restaurant DB'!B:B,'Restaurant DB'!I:I)} -> bond@hungryhub.com | S28: 45736 | T28: 0.54166667 | Z28: Check Later
B29: =XLOOKUP(C29,'KOL database'!$C$2:$C$869,'KOL database'!$B$2:$B$869) -> #REF! | C29: sgadventurousduo | D29: 117433 | E29: {=XLOOKUP(G29,'Restaurant DB All'!$B$32:$B$5758,'Restaurant DB All'!$I$32:$I$5758)} -> Bangkok | G29: NAMA Japanese and Seafood Buffet (Hungry Hub) | H29: {=XLOOKUP(G29,'Restaurant DB'!B:B,'Restaurant DB'!A:A)} -> 5149 | I29: {=XLOOKUP(G29,'Restaurant DB'!B:B,'Restaurant DB'!N:N)} -> Japanese | J29: All You Can Eat | K29: 1650 | L29: Premium Box 1 Set + Exclusive Menu + Buffet Line (Mon-Fri) | O29: 5905.4996 | Q29: Approved | R29: {=XLOOKUP(G29,'Restaurant DB'!B:B,'Restaurant DB'!I:I)} -> earth@hungryhub.com | S29: 45737 | T29: 0.54166667 | Z29: Check Later
B30: =XLOOKUP(C30,'KOL database'!$C$2:$C$869,'KOL database'!$B$2:$B$869) -> #REF! | C30: howtotravelfulltime | D30: 100047 | E30: {=XLOOKUP(G30,'Restaurant DB All'!$B$32:$B$5758,'Restaurant DB All'!$I$32:$I$5758)} -> Bangkok | G30: About Beef Lava Grill | H30: {=XLOOKUP(G30,'Restaurant DB'!B:B,'Restaurant DB'!A:A)} -> 4751 | I30: {=XLOOKUP(G30,'Restaurant DB'!B:B,'Restaurant DB'!N:N)} -> Japanese, Fusion, Thai | J30: All You Can Eat | K30: 1159 | L30: Premium International Buffet (Only for Hungry Hub) | O30: 13500 | Q30: Approved | R30: {=XLOOKUP(G30,'Restaurant DB'!B:B,'Restaurant DB'!I:I)} -> dew@hungryhub.com | S30: 45738 | T30: 0.70833333 | Z30: Check Later
B31: =XLOOKUP(C31,'KOL database'!$C$2:$C$869,'KOL database'!$B$2:$B$869) -> #REF! | C31: sgadventurousduo | D31: 117433 | E31: {=XLOOKUP(G31,'Restaurant DB All'!$B$32:$B$5758,'Restaurant DB All'!$I$32:$I$5758)} -> Bangkok | G31: Baan Dalaa by Angkana | H31: {=XLOOKUP(G31,'Restaurant DB'!B:B,'Restaurant DB'!A:A)} -> 4778 | I31: {=XLOOKUP(G31,'Restaurant DB'!B:B,'Restaurant DB'!N:N)} -> Thai Southern, Thai | J31: Party Pack | K31: 1350 | L31: Sharing Set for 2 People | O31: 5905.4996 | Q31: Approved | R31: {=XLOOKUP(G31,'Restaurant DB'!B:B,'Restaurant DB'!I:I)} -> dew@hungryhub.com | S31: 45738 | T31: 0.5 | Z31: Check Later
B32: =XLOOKUP(C32,'KOL database'!$C$2:$C$869,'KOL database'!$B$2:$B$869) -> #REF! | C32: sgadventurousduo | D32: 117433 | E32: {=XLOOKUP(G32,'Restaurant DB All'!$B$32:$B$5758,'Restaurant DB All'!$I$32:$I$5758)} -> Bangkok | G32: Butcher Factory by Bangkok Butcher | H32: {=XLOOKUP(G32,'Restaurant DB'!B:B,'Restaurant DB'!A:A)} -> 4178 | I32: {=XLOOKUP(G32,'Restaurant DB'!B:B,'Restaurant DB'!N:N)} -> Steakhouse, Italian, International, American, European | J32: All You Can Eat | K32: 1690 | L32: Premium Dry Aged Gentle Butcher Buffet Steak) | O32: 5905.4996 | Q32: Approved | R32: {=XLOOKUP(G32,'Restaurant DB'!B:B,'Restaurant DB'!I:I)} -> earth@hungryhub.com | S32: 45739 | T32: 0.5 | Z32: Check Later
B33: HH-INJKO | C33: jkonthego | D33: 38900 | E33: Bangkok | G33: Copper Beyond Buffet Gaysorn Amarin (Hungry Hub) | H33: {=XLOOKUP(G33,'Restaurant DB'!B:B,'Restaurant DB'!A:A)} -> 4503 | I33: {=XLOOKUP(G33,'Restaurant DB'!B:B,'Restaurant DB'!N:N)} -> European, Fusion, International, Japanese, Thai | J33: All You Can Eat | K33: 2599 | L33: Hungry Hub Pack A - Select 1 Premium Menu | O33: 1670.6514 | P33: TRUE | Q33: Approved | R33: {=XLOOKUP(G33,'Restaurant DB'!B:B,'Restaurant DB'!I:I)} -> surasit@hungryhub.com | S33: 45740 | T33: 0.8125 | U33: 1 | V33: Booked | X33: 7356179 | Y33: 45741 | Z33: Check Later
B34: =XLOOKUP(C34,'KOL database'!$C$2:$C$869,'KOL database'!$B$2:$B$869) -> #REF! | C34: eaterries | D34: 26326 | E34: Singapore | G34: Bar Cicheti | H34: {=XLOOKUP(G34,'Restaurant DB'!B:B,'Restaurant DB'!A:A)} -> 5343 | I34: {=XLOOKUP(G34,'Restaurant DB'!B:B,'Restaurant DB'!N:N)} -> Italian | J34: Party Pack | K34: 76 | L34: 3-Course Set Dinner Menu | O34: 5062.58 | Q34: Approved | R34: {=XLOOKUP(G34,'Restaurant DB'!B:B,'Restaurant DB'!I:I)} -> fred@hungryhub.com | S34: 45741 | T34: 0.79166667 | U34: 2 | V34: Booked | X34: 7326718 | Z34: Check Later
B35: =XLOOKUP(C35,'KOL database'!$C$2:$C$869,'KOL database'!$B$2:$B$869) -> #REF! | C35: jkonthego | D35: 38900 | E35: {=XLOOKUP(G35,'Restaurant DB All'!$B$32:$B$5758,'Restaurant DB All'!$I$32:$I$5758)} -> Bangkok | G35: Great Harbour International Buffet | H35: {=iferror(XLOOKUP(G35,'Restaurant DB'!B:B,'Restaurant DB'!A:A),".")} -> 3005 | I35: {=XLOOKUP(G35,'Restaurant DB'!B:B,'Restaurant DB'!N:N)} -> Chinese, European, Fusion, International, Japanese, Thai | J35: All You Can Eat | K35: 1493 | L35: Standard Buffet + Durian Buffet | O35: 1670.6514 | P35: TRUE | Q35: Approved | R35: {=XLOOKUP(G35,'Restaurant DB'!B:B,'Restaurant DB'!I:I)} -> bond@hungryhub.com | S35: 45741 | T35: 0.5 | U35: 1 | V35: Booked | X35: 7359498 | Y35: 45747 | Z35: Check Later
B36: =XLOOKUP(C36,'KOL database'!$C$2:$C$869,'KOL database'!$B$2:$B$869) -> #REF! | C36: jkonthego | D36: 38900 | E36: {=XLOOKUP(G36,'Restaurant DB All'!$B$32:$B$5758,'Restaurant DB All'!$I$32:$I$5758)} -> Bangkok | F36: instagram.com/jkonthego | G36: Dark Waters Rooftop Bar & Riverside | H36: {=iferror(XLOOKUP(G36,'Restaurant DB'!B:B,'Restaurant DB'!A:A),".")} -> 4511 | I36: {=XLOOKUP(G36,'Restaurant DB'!B:B,'Restaurant DB'!N:N)} -> International, Fusion, Thai | J36: Party Pack | K36: 1990 | L36: Romantic Set for 2 People (Advance 1 Day) | O36: 1670.6514 | P36: TRUE | Q36: Approved | R36: {=XLOOKUP(G36,'Restaurant DB'!B:B,'Restaurant DB'!I:I)} -> bond@hungryhub.com | S36: 45741 | T36: 0.79166667 | U36: 1 | V36: Booked | X36: 7359514 | Y36: 45743 | Z36: Check Later
B37: =XLOOKUP(C37,'KOL database'!$C$2:$C$869,'KOL database'!$B$2:$B$869) -> #REF! | C37: bangkok.discovery | D37: 199227 | E37: {=XLOOKUP(G37,'Restaurant DB All'!$B$32:$B$5758,'Restaurant DB All'!$I$32:$I$5758)} -> Bangkok | F37: Instagram.com/bangkok.discovery | G37: Oishi Grand Siam Paragon | H37: {=iferror(XLOOKUP(G37,'Restaurant DB'!B:B,'Restaurant DB'!A:A),".")} -> 4039 | I37: {=XLOOKUP(G37,'Restaurant DB'!B:B,'Restaurant DB'!N:N)} -> European, Fusion, International, Japanese | J37: All You Can Eat | K37: 2799 | L37: Oishi Grand: Prestige Buffet | O37: 20250.32 | Q37: Approved | R37: {=XLOOKUP(G37,'Restaurant DB'!B:B,'Restaurant DB'!I:I)} -> bond@hungryhub.com | S37: 45741 | T37: 0.5 | U37: 2 | V37: Validated | Z37: Check Later
B38: =XLOOKUP(C38,'KOL database'!$C$2:$C$869,'KOL database'!$B$2:$B$869) -> #REF! | C38: jkonthego | D38: 38900 | E38: {=XLOOKUP(G38,'Restaurant DB All'!$B$32:$B$5758,'Restaurant DB All'!$I$32:$I$5758)} -> Bangkok | F38: instagram.com/jkonthegoV2 | G38: The Seafood Cafe & Restaurant | H38: {=iferror(XLOOKUP(G38,'Restaurant DB'!B:B,'Restaurant DB'!A:A),".")} -> 1433 | I38: {=XLOOKUP(G38,'Restaurant DB'!B:B,'Restaurant DB'!N:N)} -> Thai, Chinese, International, Fusion | J38: All You Can Eat | K38: 2999 | L38: Lobster Lover Set for 4 People | O38: 1670.6514 | P38: TRUE | Q38: Approved | R38: {=XLOOKUP(G38,'Restaurant DB'!B:B,'Restaurant DB'!I:I)} -> sirirat@hungryhub.com | S38: 45742 | T38: 0.45833333 | U38: 1 | V38: Booked | X38: 7356205 | Y38: 45762 | Z38: Check Later
B39: HH-INJKO | C39: jkonthego | D39: 38900 | E39: Bangkok | G39: Gentle Butcher by Bangkok Butcher | H39: {=XLOOKUP(G39,'Restaurant DB'!B:B,'Restaurant DB'!A:A)} -> 4889 | I39: {=XLOOKUP(G39,'Restaurant DB'!B:B,'Restaurant DB'!N:N)} -> Steakhouse, Fusion, American, Mexican | J39: All You Can Eat | K39: 1690 | L39: Premium Dry Aged Gentle Butcher Buffet Steak | O39: 1670.6514 | P39: TRUE | Q39: Approved | R39: {=XLOOKUP(G39,'Restaurant DB'!B:B,'Restaurant DB'!I:I)} -> earth@hungryhub.com | S39: 45742 | T39: 0.79166667 | U39: 1 | V39: Booked | X39: 7360875 | Y39: 45755 | Z39: Check Later
B40: HH-LOBAE | C40: bangkok.vibe | D40: 33382 | E40: Bangkok | F40: https://www.instagram.com/bangkok.vibe/ | G40: Kam's Roast Central World | H40: {=XLOOKUP(G40,'Restaurant DB'!B:B,'Restaurant DB'!A:A)} -> 5251 | I40: {=XLOOKUP(G40,'Restaurant DB'!B:B,'Restaurant DB'!N:N)} -> Chinese | J40: Party Pack | K40: 1190 | L40: Premium Set for 2 People | O40: 10125.16 | Q40: Approved | R40: {=XLOOKUP(G40,'Restaurant DB'!B:B,'Restaurant DB'!I:I)} -> earth@hungryhub.com | S40: 45742 | T40: 0.5 | U40: 2 | V40: Validated | Z40: Check Later
...

Sheet Booking SG
B1: KOL_ID | C1: Username | D1: Followers | E1: Country | F1: Social media URL | G1: Restaurant name | H1: Restaurant ID | I1: Cuisine Type | J1: Package Type | K1: Package price | L1: Package Name | M1: Allergies | N1: Comments | O1: Fee per content | P1: Column 15 | Q1: Column 16 | R1: Column 17 | S1: Target Date | T1: Target time | U1: No people | V1: Sales Check | W1: Line_thread_id | X1: Booking ID | Y1: Target post date | Z1: Post details | AA1: Notes | AB1: index
B2: HH-TESTING | C2: TESTING | D2: 12345 | E2: Test city | F2: ig.com/testing | G2: tesitng restaurant | H2: {=XLOOKUP(G2,'Restaurant DB All'!B:B,'Restaurant DB All'!A:A)} -> #N/A | I2: {=XLOOKUP(G2,'Restaurant DB'!B:B,'Restaurant DB'!N:N)} -> #N/A | J2: Party Pack | K2: 1234 | L2: Testing menu | M2: Testing alergies | N2: Test comments | O2: 12345 | P2: FALSE | R2: {=XLOOKUP(G2,'Restaurant DB'!B:B,'Restaurant DB'!I:I)} -> #N/A | S2: 33156 | T2: 0.75 | U2: 20 | V2: Asked Guillaume | W2: 588528281180176784 | Z2: TEST | AB2: HH-TESTINGXDE71
B3: HH-TESTING | C3: TESTING | D3: 12345 | E3: Test city | F3: ig.com/testing | G3: test 4 | H3: {=XLOOKUP(G3,'Restaurant DB All'!B:B,'Restaurant DB All'!A:A)} -> #N/A | I3: {=XLOOKUP(G3,'Restaurant DB'!B:B,'Restaurant DB'!N:N)} -> #N/A | J3: Party Pack | K3: 1234 | L3: Testing menu | M3: Testing alergies | N3: Test comments | O3: 12345 | P3: FALSE | R3: {=XLOOKUP(G3,'Restaurant DB'!B:B,'Restaurant DB'!I:I)} -> #N/A | S3: 33177 | T3: 0.79166667 | U3: 100 | V3: Asked Guillaume | W3: 588528294350291663 | Z3: TEST | AB3: HH-TESTINGQHU28
B4: HH-TESTING | C4: TESTING | D4: 12345 | E4: Test city | F4: ig.com/testing | G4: test 3 | H4: {=XLOOKUP(G4,'Restaurant DB All'!B:B,'Restaurant DB All'!A:A)} -> #N/A | I4: {=XLOOKUP(G4,'Restaurant DB'!B:B,'Restaurant DB'!N:N)} -> #N/A | J4: Party Pack | K4: 1234 | L4: Testing menu | M4: Testing alergies | N4: Test comments | O4: 12345 | P4: FALSE | R4: {=XLOOKUP(G4,'Restaurant DB'!B:B,'Restaurant DB'!I:I)} -> #N/A | S4: 33217 | T4: 0.41666667 | U4: 50 | V4: Asked Guillaume | W4: 588528289937883222 | Z4: TEST | AB4: HH-TESTINGYSO07
B5: HH-TESTING | C5: TESTING | D5: 12345 | E5: Test city | F5: ig.com/testing | G5: test 2 | H5: {=XLOOKUP(G5,'Restaurant DB All'!B:B,'Restaurant DB All'!A:A)} -> #N/A | I5: {=XLOOKUP(G5,'Restaurant DB'!B:B,'Restaurant DB'!N:N)} -> #N/A | J5: Party Pack | K5: 1234 | L5: Testing menu | M5: Testing alergies | N5: Test comments | O5: 12345 | P5: FALSE | R5: {=XLOOKUP(G5,'Restaurant DB'!B:B,'Restaurant DB'!I:I)} -> #N/A | S5: 44510 | T5: 0.75 | U5: 10 | V5: Asked Guillaume | W5: 588528285491921411 | Z5: TEST | AB5: HH-TESTINGLNF73
B6: {=XLOOKUP(C6,'KOL database'!$C$2:$C$869,'KOL database'!$B$2:$B$869)} -> #REF! | C6: eaterries | D6: 26326 | E6: Singapore | G6: Warm Up Cafe @ Mackenzie Road | H6: {=XLOOKUP(G6,'Restaurant DB All'!B:B,'Restaurant DB All'!A:A)} -> 5318 | I6: {=XLOOKUP(G6,'Restaurant DB'!B:B,'Restaurant DB'!N:N)} -> Thai | J6: Party Pack | K6: 69 | L6: Sharing Set for 2 People | O6: 5062.58 | Q6: Approved | R6: {=XLOOKUP(G6,'Restaurant DB'!B:B,'Restaurant DB'!I:I)} -> fred@hungryhub.com | S6: 45713 | T6: 0.77083333 | U6: 2 | V6: Booked | X6: 7186274 | Z6: Check Later
B7: HH-SGMEY | C7: melicacy | D7: 44191 | E7: {=XLOOKUP(G7,'Restaurant DB All'!$B$32:$B$5758,'Restaurant DB All'!$I$32:$I$5758)} -> Singapore | F7: Instagram.com/melicacy | G7: Forma | H7: {=XLOOKUP(G7,'Restaurant DB All'!B:B,'Restaurant DB All'!A:A)} -> 5345 | I7: {=XLOOKUP(G7,'Restaurant DB'!B:B,'Restaurant DB'!N:N)} -> Italian | J7: Party Pack | K7: 112 | L7: 3-COURSE WINTER SET DINNER | O7: 5062.58 | R7: {=XLOOKUP(G7,'Restaurant DB'!B:B,'Restaurant DB'!I:I)} -> fred@hungryhub.com | S7: 45713 | T7: 0.79166667 | U7: 2 | V7: Booked | Z7: {=if(iferror(INDEX(Posts[Username],MATCH(C7&G7,Posts[Username]&Posts[Restaurant Name],0)),"")=C7,"Posted","")} -> Posted
B8: HH-SGMEY | C8: melicacy | D8: 44191 | E8: {=XLOOKUP(G8,'Restaurant DB All'!$B$32:$B$5758,'Restaurant DB All'!$I$32:$I$5758)} -> Singapore | F8: Instagram.com/melicacy | G8: Wild Child Pizzette | H8: {=XLOOKUP(G8,'Restaurant DB All'!B:B,'Restaurant DB All'!A:A)} -> 5344 | I8: {=XLOOKUP(G8,'Restaurant DB'!B:B,'Restaurant DB'!N:N)} -> Italian | J8: Party Pack | K8: 151 | L8: Sharing Set for 2 People | O8: 5062.58 | R8: {=XLOOKUP(G8,'Restaurant DB'!B:B,'Restaurant DB'!I:I)} -> fred@hungryhub.com | S8: 45714 | T8: 0.79166667 | U8: 2 | V8: Booked | Z8: Check Later
B9: HH-SGMEY | C9: melicacy | D9: 44191 | E9: {=XLOOKUP(G9,'Restaurant DB All'!$B$32:$B$5758,'Restaurant DB All'!$I$32:$I$5758)} -> Singapore | F9: Instagram.com/melicacy | G9: Mizuya Omakase | H9: {=XLOOKUP(G9,'Restaurant DB All'!B:B,'Restaurant DB All'!A:A)} -> 5362 | I9: {=XLOOKUP(G9,'Restaurant DB'!B:B,'Restaurant DB'!N:N)} -> Japanese | J9: Party Pack | K9: 155 | L9: Special x2 Omakase 7 Course With Free Flow Green Tea | O9: 5062.58 | R9: {=XLOOKUP(G9,'Restaurant DB'!B:B,'Restaurant DB'!I:I)} -> fred@hungryhub.com | S9: 45720 | T9: 0.79166667 | U9: 2 | V9: Booked | Z9: {=if(iferror(INDEX(Posts[Username],MATCH(C9&G9,Posts[Username]&Posts[Restaurant Name],0)),"")=C9,"Posted","")} -> Posted
B10: HH-LOTHI | C10: thara_koiii | D10: 95611 | E10: {=XLOOKUP(G10,'Restaurant DB All'!$B$32:$B$5758,'Restaurant DB All'!$I$32:$I$5758)} -> Singapore | F10: Instagram.com/thara_koiii | G10: Colony At The Ritz-Carlton, Millenia Singapore | H10: {=XLOOKUP(G10,'Restaurant DB All'!B:B,'Restaurant DB All'!A:A)} -> 5412 | I10: {=XLOOKUP(G10,'Restaurant DB'!B:B,'Restaurant DB'!N:N)} -> International, Singaporean | J10: All You Can Eat | K10: 89 | L10: Lunch Buffet (Mon-Fri) | O10: 1685.8391 | R10: {=XLOOKUP(G10,'Restaurant DB'!B:B,'Restaurant DB'!I:I)} -> fred@hungryhub.com | S10: 45726 | T10: 0.5 | U10: 2 | V10: Booked | Z10: {=if(iferror(INDEX(Posts[Username],MATCH(C10&G10,Posts[Username]&Posts[Restaurant Name],0)),"")=C10,"Posted","")} -> Posted
B11: =XLOOKUP(C11,'KOL database'!$C$2:$C$869,'KOL database'!$B$2:$B$869) -> #REF! | C11: eaterries | D11: 26326 | E11: Singapore | G11: Wild Child Pizzette | H11: {=XLOOKUP(G11,'Restaurant DB All'!B:B,'Restaurant DB All'!A:A)} -> 5344 | I11: {=XLOOKUP(G11,'Restaurant DB'!B:B,'Restaurant DB'!N:N)} -> Italian | J11: Party Pack | K11: 151 | L11: Sharing Set for 2 People | O11: 5062.58 | Q11: Approved | R11: {=XLOOKUP(G11,'Restaurant DB'!B:B,'Restaurant DB'!I:I)} -> fred@hungryhub.com | S11: 45731 | T11: 0.54166667 | U11: 2 | V11: Booked | X11: 7175926 | Z11: Check Later
B12: =XLOOKUP(C12,'KOL database'!$C$2:$C$869,'KOL database'!$B$2:$B$869) -> #REF! | C12: eaterries | D12: 26326 | E12: Singapore | G12: Fook Kin 福劲 | H12: {=XLOOKUP(G12,'Restaurant DB All'!B:B,'Restaurant DB All'!A:A)} -> 5376 | I12: {=XLOOKUP(G12,'Restaurant DB'!B:B,'Restaurant DB'!N:N)} -> Chinese, Singaporean | J12: Party Pack | K12: 76 | L12: Sharing Set for 2 People | O12: 5062.58 | Q12: Approved | R12: {=XLOOKUP(G12,'Restaurant DB'!B:B,'Restaurant DB'!I:I)} -> fred@hungryhub.com | S12: 45734 | T12: 0.79166667 | U12: 2 | V12: Booked | X12: 7344487 | Z12: Check Later
B13: =XLOOKUP(C13,'KOL database'!$C$2:$C$869,'KOL database'!$B$2:$B$869) -> #REF! | C13: eaterries | D13: 26326 | E13: Singapore | G13: Bar Cicheti | H13: {=XLOOKUP(G13,'Restaurant DB All'!B:B,'Restaurant DB All'!A:A)} -> 5343 | I13: {=XLOOKUP(G13,'Restaurant DB'!B:B,'Restaurant DB'!N:N)} -> Italian | J13: Party Pack | K13: 76 | L13: 3-Course Set Dinner Menu | O13: 5062.58 | Q13: Approved | R13: {=XLOOKUP(G13,'Restaurant DB'!B:B,'Restaurant DB'!I:I)} -> fred@hungryhub.com | S13: 45741 | T13: 0.79166667 | U13: 2 | V13: Booked | X13: 7326718 | Z13: Check Later
B14: HH-LOTHI | C14: thara_koiii | D14: 95611 | E14: {=XLOOKUP(G14,'Restaurant DB All'!$B$32:$B$5758,'Restaurant DB All'!$I$32:$I$5758)} -> Singapore | F14: Instagram.com/thara_koiii | G14: Hai Tien Lo at Pan Pacific Hotel Singapore | H14: {=XLOOKUP(G14,'Restaurant DB All'!B:B,'Restaurant DB All'!A:A)} -> 5457 | I14: {=XLOOKUP(G14,'Restaurant DB'!B:B,'Restaurant DB'!N:N)} -> Chinese | J14: Party Pack | K14: 110 | L14: Hai Tien Lo l 5-Course Dinner Set | O14: 1685.8391 | R14: {=XLOOKUP(G14,'Restaurant DB'!B:B,'Restaurant DB'!I:I)} -> fred@hungryhub.com | S14: 45749 | T14: 0.75 | U14: 2 | V14: Booked | Z14: {=if(iferror(INDEX(Posts[Username],MATCH(C14&G14,Posts[Username]&Posts[Restaurant Name],0)),"")=C14,"Posted","")} -> Posted
B15: HH-INJKO | C15: jkonthego | D15: 38900 | E15: Singapore | G15: Oh Ho Thai BBQ | H15: {=XLOOKUP(G15,'Restaurant DB All'!B:B,'Restaurant DB All'!A:A)} -> 5474 | I15: {=XLOOKUP(G15,'Restaurant DB'!B:B,'Restaurant DB'!N:N)} -> #N/A | J15: Party Pack | K15: 34 | L15: Sharing Set for 2 People (Book 2 Hours in Advance) | O15: 1670.6514 | P15: FALSE | Q15: Approved | R15: {=XLOOKUP(G15,'Restaurant DB'!B:B,'Restaurant DB'!I:I)} -> #N/A | S15: 45763 | T15: 0.5 | U15: 2 | V15: Booked | X15: 7398610 | Z15: Check Later
B16: HH-INTAZ | C16: tachichosz | D16: 70870 | E16: Singapore | G16: Bone Apple Tea Bistro | H16: {=XLOOKUP(G16,'Restaurant DB All'!B:B,'Restaurant DB All'!A:A)} -> 5738 | I16: {=XLOOKUP(G16,'Restaurant DB'!B:B,'Restaurant DB'!N:N)} -> Fusion | J16: Party Pack | K16: 69 | L16: Lunch Set for 2 people | O16: 14152.5 | P16: TRUE | Q16: Approved | R16: {=XLOOKUP(G16,'Restaurant DB'!B:B,'Restaurant DB'!I:I)} -> fred@hungryhub.com | S16: 45764 | T16: 0.66666667 | U16: 2 | V16: Booked | X16: 7419684 | Y16: 45804 | Z16: {=if(iferror(INDEX(Posts[Username],MATCH(C16&G16,Posts[Username]&Posts[Restaurant Name],0)),"")=C16,"Posted","")} -> Posted
B17: HH-INJKO | C17: jkonthego | D17: 38900 | E17: Singapore | G17: Home Dusk: Live House | H17: {=XLOOKUP(G17,'Restaurant DB All'!B:B,'Restaurant DB All'!A:A)} -> 5648 | I17: {=XLOOKUP(G17,'Restaurant DB'!B:B,'Restaurant DB'!N:N)} -> International, Italian, Japanese, Fusion, Korean, American | J17: Party Pack | K17: 130 | L17: Sharing Set for 2 people | O17: 1670.6514 | P17: FALSE | Q17: Approved | R17: {=XLOOKUP(G17,'Restaurant DB'!B:B,'Restaurant DB'!I:I)} -> fred@hungryhub.com | S17: 45764 | T17: 0.77083333 | U17: 2 | V17: Booked | X17: 7398617 | Z17: Check Later
B18: HH-INTAZ | C18: tachichosz | D18: 70870 | E18: Singapore | G18: Waterfall Lounge at Furama Riverfront Hotel | H18: {=XLOOKUP(G18,'Restaurant DB All'!B:B,'Restaurant DB All'!A:A)} -> 5643 | I18: {=XLOOKUP(G18,'Restaurant DB'!B:B,'Restaurant DB'!N:N)} -> Chinese, European | J18: Party Pack | K18: 50 | L18: Waterfall l Tea Bliss Set for 2 People | O18: 14152.5 | P18: TRUE | Q18: Approved | R18: {=XLOOKUP(G18,'Restaurant DB'!B:B,'Restaurant DB'!I:I)} -> fred@hungryhub.com | S18: 45765 | T18: 0.64583333 | U18: 2 | V18: Booked | X18: 7422629 | Y18: 45777 | Z18: Check Later
B19: HH-INTAZ | C19: tachichosz | D19: 70870 | E19: Singapore | G19: Grand Konak Turkish and Lebanese Restaurant | H19: {=XLOOKUP(G19,'Restaurant DB All'!B:B,'Restaurant DB All'!A:A)} -> 5813 | I19: {=XLOOKUP(G19,'Restaurant DB'!B:B,'Restaurant DB'!N:N)} -> Egyptian, Mediterranean, Lebanese, Turkish, Middle Eastern | J19: Party Pack | K19: 199 | L19: Sharing Set for 2 people | O19: 14152.5 | P19: TRUE | Q19: Approved | R19: {=XLOOKUP(G19,'Restaurant DB'!B:B,'Restaurant DB'!I:I)} -> fred@hungryhub.com | S19: 45765 | T19: 0.47916667 | U19: 2 | V19: Booked | X19: 7421309 | Y19: 45775 | Z19: {=if(iferror(INDEX(Posts[Username],MATCH(C19&G19,Posts[Username]&Posts[Restaurant Name],0)),"")=C19,"Posted","")} -> Posted
B20: HH-INTAZ | C20: tachichosz | D20: 70870 | E20: Singapore | G20: Taksim Restaurant | H20: {=XLOOKUP(G20,'Restaurant DB All'!B:B,'Restaurant DB All'!A:A)} -> 5736 | I20: {=XLOOKUP(G20,'Restaurant DB'!B:B,'Restaurant DB'!N:N)} -> Egyptian, Mediterranean, Lebanese, Middle Eastern | J20: Party Pack | K20: 99 | L20: Sharing Set for 2 people | O20: 14152.5 | P20: TRUE | Q20: Approved | R20: {=XLOOKUP(G20,'Restaurant DB'!B:B,'Restaurant DB'!I:I)} -> fred@hungryhub.com | S20: 45766 | T20: 0.83333333 | U20: 2 | V20: Booked | X20: 7419713 | Y20: 45800 | Z20: {=if(iferror(INDEX(Posts[Username],MATCH(C20&G20,Posts[Username]&Posts[Restaurant Name],0)),"")=C20,"Posted","")} -> Posted
B21: HH-INTAZ | C21: tachichosz | D21: 70870 | E21: Singapore | G21: Tea Lounge at Conrad Singapore Orchard | H21: {=XLOOKUP(G21,'Restaurant DB All'!B:B,'Restaurant DB All'!A:A)} -> 5597 | I21: {=XLOOKUP(G21,'Restaurant DB'!B:B,'Restaurant DB'!N:N)} -> International | J21: All You Can Eat | K21: 76 | L21: Weekend High Tea Buffet | O21: 14152.5 | P21: TRUE | Q21: Approved | R21: {=XLOOKUP(G21,'Restaurant DB'!B:B,'Restaurant DB'!I:I)} -> fred@hungryhub.com | S21: 45766 | T21: 0.625 | U21: 2 | V21: Booked | X21: 7424025 | Y21: 45772 | Z21: {=if(iferror(INDEX(Posts[Username],MATCH(C21&G21,Posts[Username]&Posts[Restaurant Name],0)),"")=C21,"Posted","")} -> Posted
B22: HH-INJKO | C22: jkonthego | D22: 38900 | E22: Singapore | G22: Fook Kin 福劲 | H22: {=XLOOKUP(G22,'Restaurant DB All'!B:B,'Restaurant DB All'!A:A)} -> 5376 | I22: {=XLOOKUP(G22,'Restaurant DB'!B:B,'Restaurant DB'!N:N)} -> Chinese, Singaporean | J22: Party Pack | K22: 76 | L22: Sharing Set for 2 People | O22: 1670.6514 | P22: FALSE | Q22: Approved | R22: {=XLOOKUP(G22,'Restaurant DB'!B:B,'Restaurant DB'!I:I)} -> fred@hungryhub.com | S22: 45770 | T22: 0.47916667 | U22: 2 | V22: Booked | X22: 7398622 | Z22: Check Later
B23: HH-SGLIE | C23: liveloveatwithjie | D23: 20920 | E23: Singapore | G23: Mama Diam 妈妈店 | H23: {=XLOOKUP(G23,'Restaurant DB All'!B:B,'Restaurant DB All'!A:A)} -> 5735 | I23: {=XLOOKUP(G23,'Restaurant DB'!B:B,'Restaurant DB'!N:N)} -> Singaporean, Chinese | J23: Party Pack | K23: 108 | L23: Sharing Set for 2 People | O23: 5062.58 | Q23: Approved | R23: {=XLOOKUP(G23,'Restaurant DB'!B:B,'Restaurant DB'!I:I)} -> fred@hungryhub.com | S23: 45822 | T23: 0.79166667 | U23: 2 | V23: Booked | X23: 7700367 | Z23: {=if(iferror(INDEX(Posts[Username],MATCH(C23&G23,Posts[Username]&Posts[Restaurant Name],0)),"")=C23,"Posted","")} -> Posted
B24: HH-SGMEY | C24: melicacy | D24: 44191 | E24: {=XLOOKUP(G24,'Restaurant DB All'!$B$32:$B$5758,'Restaurant DB All'!$I$32:$I$5758)} -> Singapore | F24: Instagram.com/melicacy | G24: Les Bouchons at Robertson Quay | H24: {=XLOOKUP(G24,'Restaurant DB All'!B:B,'Restaurant DB All'!A:A)} -> 5640 | I24: {=XLOOKUP(G24,'Restaurant DB'!B:B,'Restaurant DB'!N:N)} -> European, French, Steakhouse | J24: Party Pack | K24: 100 | L24: A Taste of France l 3-Course Meal | O24: 5062.58 | R24: {=XLOOKUP(G24,'Restaurant DB'!B:B,'Restaurant DB'!I:I)} -> fred@hungryhub.com | S24: 45828 | T24: 0.79166667 | U24: 2 | V24: Validated | Z24: Check Later
B25: HH-LOMYG | C25: myfoodiegallerysg | D25: 30467 | E25: Singapore | G25: Enjoy Eating House and Bar | H25: {=XLOOKUP(G25,'Restaurant DB All'!B:B,'Restaurant DB All'!A:A)} -> 5462 | I25: {=XLOOKUP(G25,'Restaurant DB'!B:B,'Restaurant DB'!N:N)} -> Chinese, Singaporean | R25: {=XLOOKUP(G25,'Restaurant DB'!B:B,'Restaurant DB'!I:I)} -> fred@hungryhub.com | S25: 45831 | V25: Validated | Z25: Check Later
B26: HH-LOMYG | C26: myfoodiegallerysg | D26: 30467 | E26: Singapore | G26: Hai Tien Lo at Pan Pacific Hotel Singapore | H26: {=XLOOKUP(G26,'Restaurant DB All'!B:B,'Restaurant DB All'!A:A)} -> 5457 | I26: {=XLOOKUP(G26,'Restaurant DB'!B:B,'Restaurant DB'!N:N)} -> Chinese | R26: {=XLOOKUP(G26,'Restaurant DB'!B:B,'Restaurant DB'!I:I)} -> fred@hungryhub.com | S26: 45834 | V26: Validated | Z26: {=if(iferror(INDEX(Posts[Username],MATCH(C26&G26,Posts[Username]&Posts[Restaurant Name],0)),"")=C26,"Posted","")} -> Posted
B27: HH-SGLIE | C27: liveloveatwithjie | D27: 20920 | E27: Singapore | G27: Edge at Pan Pacific Hotel Singapore | H27: {=XLOOKUP(G27,'Restaurant DB All'!B:B,'Restaurant DB All'!A:A)} -> 5465 | I27: {=XLOOKUP(G27,'Restaurant DB'!B:B,'Restaurant DB'!N:N)} -> International | J27: All You Can Eat | K27: 97 | L27: Weekday Dinner Buffet (Sun-Thu) | O27: 5062.58 | Q27: Approved | R27: {=XLOOKUP(G27,'Restaurant DB'!B:B,'Restaurant DB'!I:I)} -> fred@hungryhub.com | S27: 45838 | T27: 0.79166667 | U27: 2 | V27: Booked | X27: 7586879 | Y27: 45861 | Z27: {=if(iferror(INDEX(Posts[Username],MATCH(C27&G27,Posts[Username]&Posts[Restaurant Name],0)),"")=C27,"Posted","")} -> Posted
B28: HH-SGLIE | C28: liveloveatwithjie | D28: 20920 | E28: Singapore | G28: Synthesis 食拿酒稳 Chinese Cuisine | H28: {=XLOOKUP(G28,'Restaurant DB All'!B:B,'Restaurant DB All'!A:A)} -> 5637 | I28: {=XLOOKUP(G28,'Restaurant DB'!B:B,'Restaurant DB'!N:N)} -> Fusion | J28: Party Pack | K28: 248 | L28: Review date:: 30 Jun, 7PM | O28: 5062.58 | Q28: Approved | R28: {=XLOOKUP(G28,'Restaurant DB'!B:B,'Restaurant DB'!I:I)} -> fred@hungryhub.com | S28: 45847 | T28: 0.79166667 | U28: 4 | V28: Booked | X28: 7586898 | Z28: Check Later
B29: HH-INJKO | C29: jkonthego | D29: 38900 | E29: Singapore | G29: Edge at Pan Pacific Hotel Singapore | H29: {=XLOOKUP(G29,'Restaurant DB All'!B:B,'Restaurant DB All'!A:A)} -> 5465 | I29: {=XLOOKUP(G29,'Restaurant DB'!B:B,'Restaurant DB'!N:N)} -> International | J29: All You Can Eat | K29: 97 | L29: Weekday Dinner Buffet (Sun-Thu) | O29: 1670.6514 | P29: FALSE | Q29: Approved | R29: {=XLOOKUP(G29,'Restaurant DB'!B:B,'Restaurant DB'!I:I)} -> fred@hungryhub.com | S29: 45848 | T29: 0.75 | U29: 2 | V29: Booked | X29: 7671275 | Z29: {=if(iferror(INDEX(Posts[Username],MATCH(C29&G29,Posts[Username]&Posts[Restaurant Name],0)),"")=C29,"Posted","")} -> Posted
B30: HH-LOMYG | C30: myfoodiegallerysg | D30: 30467 | E30: {=XLOOKUP(G30,'Restaurant DB All'!$B$32:$B$5758,'Restaurant DB All'!$I$32:$I$5758)} -> Singapore | G30: Crossroads Buffet at Singapore Marriott Tang Plaza Hotel | H30: {=XLOOKUP(G30,'Restaurant DB All'!B:B,'Restaurant DB All'!A:A)} -> 5547 | I30: {=XLOOKUP(G30,'Restaurant DB'!B:B,'Restaurant DB'!N:N)} -> International | P30: FALSE | Q30: Approved | R30: {=XLOOKUP(G30,'Restaurant DB'!B:B,'Restaurant DB'!I:I)} -> fred@hungryhub.com | S30: 45851 | V30: Validated | Z30: {=if(iferror(INDEX(Posts[Username],MATCH(C30&G30,Posts[Username]&Posts[Restaurant Name],0)),"")=C30,"Posted","")} -> Posted
B31: HH-SIGLN | C31: globetrotterkin | D31: 31387 | E31: Singapore | F31: Instagram.com/globetrotterkin | G31: Pacific Emporium at Pan Pacific Hotel Singapore | H31: {=XLOOKUP(G31,'Restaurant DB All'!B:B,'Restaurant DB All'!A:A)} -> 5460 | I31: {=XLOOKUP(G31,'Restaurant DB'!B:B,'Restaurant DB'!N:N)} -> Singaporean | J31: Party Pack | K31: 73.4 | L31: NEW: Local-Inspired Afternoon Tea (Sat-Sun) | O31: 0 | R31: {=XLOOKUP(G31,'Restaurant DB'!B:B,'Restaurant DB'!I:I)} -> fred@hungryhub.com | S31: 45865 | T31: 0.58333333 | U31: 3 | V31: Booked | X31: 7709865 | Z31: Check Later
B32: HH-SIGLN | C32: globetrotterkin | D32: 31387 | E32: Singapore | F32: Instagram.com/globetrotterkin | G32: Shrimp Prawn Seafood | H32: {=XLOOKUP(G32,'Restaurant DB All'!B:B,'Restaurant DB All'!A:A)} -> 5211 | I32: {=XLOOKUP(G32,'Restaurant DB'!B:B,'Restaurant DB'!N:N)} -> Thai | J32: Party Pack | K32: 139 | L32: Premium Set for 3 People | N32: Blogger from KKDAY KOL :globetrotterkin IG : https://www.instagram.com/globetrotterkin/ Follower : 31K | O32: 0 | R32: {=XLOOKUP(G32,'Restaurant DB'!B:B,'Restaurant DB'!I:I)} -> fred@hungryhub.com | S32: 45867 | T32: 0.79166667 | U32: 3 | V32: Booked | X32: 7751400 | Z32: Check Later
B33: HH-SIGLN | C33: globetrotterkin | D33: 31387 | E33: {=XLOOKUP(G33,'Restaurant DB All'!$B$32:$B$5758,'Restaurant DB All'!$I$32:$I$5758)} -> Singapore | F33: Instagram.com/globetrotterkin | G33: The Seafood Market by House of White Bee Hoon | H33: {=XLOOKUP(G33,'Restaurant DB All'!B:B,'Restaurant DB All'!A:A)} -> 5755 | I33: {=XLOOKUP(G33,'Restaurant DB'!B:B,'Restaurant DB'!N:N)} -> Chinese | J33: Party Pack | K33: 255 | L33: Sharing Set for 3 people | O33: 0 | R33: {=XLOOKUP(G33,'Restaurant DB'!B:B,'Restaurant DB'!I:I)} -> fred@hungryhub.com | S33: 45867 | T33: 0.79166667 | U33: 3 | V33: Validated | Z33: Check Later
B34: {=XLOOKUP(C34,'KOL database'!$C$2:$C$299,'KOL database'!$B$2:$B$299)} -> #REF! | C34: eaterries | D34: 26326 | E34: Singapore | G34: Enjoy Eating House and Bar | H34: {=XLOOKUP(G34,'Restaurant DB All'!B:B,'Restaurant DB All'!A:A)} -> 5462 | I34: {=XLOOKUP(G34,'Restaurant DB'!B:B,'Restaurant DB'!N:N)} -> Chinese, Singaporean | J34: Party Pack | K34: 85 | L34: Sharing Set for 2 People | O34: 5062.58 | Q34: Approved | R34: {=XLOOKUP(G34,'Restaurant DB'!B:B,'Restaurant DB'!I:I)} -> fred@hungryhub.com | S34: 45867 | T34: 0.79166667 | U34: 2 | V34: Booked | X34: 7733275 | Z34: Check Later
B35: HH-SGEAG | C35: eatsnapsg | D35: 25100 | E35: {=XLOOKUP(G35,'Restaurant DB All'!$B$32:$B$5758,'Restaurant DB All'!$I$32:$I$5758)} -> Singapore | F35: Tiktok.com/@eatsnapsg | G35: O.BBa Jjajang | H35: {=XLOOKUP(G35,'Restaurant DB All'!B:B,'Restaurant DB All'!A:A)} -> 6153 | I35: {=XLOOKUP(G35,'Restaurant DB'!B:B,'Restaurant DB'!N:N)} -> Korean | K35: 159 | L35: BBQ Set for 3 People | M35: No Dietary restrictions | N35: August Campaign | O35: 1265.645 | R35: {=XLOOKUP(G35,'Restaurant DB'!B:B,'Restaurant DB'!I:I)} -> fred@hungryhub.com | S35: 45881 | T35: 0.8125 | U35: 3 | V35: Booked | X35: 7799247 | Y35: 45897 | Z35: {=if(iferror(INDEX(Posts[Username],MATCH(C35&G35,Posts[Username]&Posts[Restaurant Name],0)),"")=C35,"Posted","")} -> Posted | AA35: Guillaume
B36: HH-INBIK | C36: bigjohnjiak | D36: 48879 | E36: {=XLOOKUP(G36,'Restaurant DB All'!$B$32:$B$5758,'Restaurant DB All'!$I$32:$I$5758)} -> Singapore | G36: Nozomi at Millenia Walk | H36: {=XLOOKUP(G36,'Restaurant DB All'!B:B,'Restaurant DB All'!A:A)} -> 5594 | I36: {=XLOOKUP(G36,'Restaurant DB'!B:B,'Restaurant DB'!N:N)} -> Japanese | J36: All You Can Eat | K36: 139 | L36: Nozomi l Premium Buffet & 1 Special Menu | M36: None | N36: August Campaign, Instagram : https://www.instagram.com/bigjohnjiak/ | O36: 12656.45 | Q36: Approved | R36: {=XLOOKUP(G36,'Restaurant DB'!B:B,'Restaurant DB'!I:I)} -> fred@hungryhub.com | S36: 45881 | T36: 0.47916667 | U36: 2 | V36: Booked | W36: 573865938483937496 | X36: 7826084 | Z36: {=if(iferror(INDEX(Posts[Username],MATCH(C36&G36,Posts[Username]&Posts[Restaurant Name],0)),"")=C36,"Posted","")} -> Posted | AA36: Sirada
B37: HH-SGGIS | C37: girldevours | D37: 2338 | E37: {=XLOOKUP(G37,'Restaurant DB All'!$B$32:$B$5758,'Restaurant DB All'!$I$32:$I$5758)} -> Singapore | F37: Tiktok.com/@girldevours | G37: Wild Child Pizzette | H37: {=XLOOKUP(G37,'Restaurant DB All'!B:B,'Restaurant DB All'!A:A)} -> 5344 | I37: {=XLOOKUP(G37,'Restaurant DB'!B:B,'Restaurant DB'!N:N)} -> Italian | J37: Party Pack | K37: 115 | L37: Sharing set for 2 | M37: None | N37: August Campaign | O37: 1518.774 | R37: {=XLOOKUP(G37,'Restaurant DB'!B:B,'Restaurant DB'!I:I)} -> fred@hungryhub.com | S37: 45885 | T37: 0.75 | U37: 2 | V37: Booked | W37: 573456397380092487 | X37: 7833694 | Y37: 45893 | Z37: {=if(iferror(INDEX(Posts[Username],MATCH(C37&G37,Posts[Username]&Posts[Restaurant Name],0)),"")=C37,"Posted","")} -> Posted | AA37: Guillaume
B38: HH-INPAR | C38: parttimefoodblogger | D38: 16406 | E38: Singapore | F38: Instagram.com/parttimefoodblogger | G38: Baia Rooftop Dining Lounge Bar | H38: {=XLOOKUP(G38,'Restaurant DB All'!B:B,'Restaurant DB All'!A:A)} -> 5647 | I38: {=XLOOKUP(G38,'Restaurant DB'!B:B,'Restaurant DB'!N:N)} -> Fusion | J38: Party Pack | K38: 228 | L38: Sharing Set for 4 People | M38: None | N38: August Campaign, Instagram : https://www.instagram.com/parttimefoodblogger/ (will post on Tiktok too) | O38: 10125.16 | R38: {=XLOOKUP(G38,'Restaurant DB'!B:B,'Restaurant DB'!I:I)} -> fred@hungryhub.com | S38: 45887 | T38: 0.79166667 | U38: 4 | V38: Refused | W38: 574165946647183599 | Z38: {=if(iferror(INDEX(Posts[Username],MATCH(C38&G38,Posts[Username]&Posts[Restaurant Name],0)),"")=C38,"Posted","")} | AA38: Sirada | AB38: HH-INPARXEU
B39: HH-INROA | C39: roadtrippers.asia | D39: 51300 | E39: Singapore | F39: Tiktok.com/@roadtrippers.asia | G39: Riviera | H39: {=XLOOKUP(G39,'Restaurant DB All'!B:B,'Restaurant DB All'!A:A)} -> 6087 | I39: {=XLOOKUP(G39,'Restaurant DB'!B:B,'Restaurant DB'!N:N)} -> Fusion, French, Mediterranean | J39: All You Can Eat | K39: 169.2 | L39: Lunch course 3 meals - 3 pax | M39: None | N39: August Campaign Tiktok https://www.tiktok.com/@roadtrippers.asia IG https://www.instagram.com/eatwithandrewchan Facebook https://www.facebook.com/@roadtrippers.asia Lemon8 https://www.lemon8-app.com/@roadtrippers.asia Xiao Hong Shu https://www.xiaohongshu.com/user/profile/66b9854e000000001d020eb8 Youtube https://youtube.com/@roadtrippers-asia | O39: 7593.87 | R39: {=XLOOKUP(G39,'Restaurant DB'!B:B,'Restaurant DB'!I:I)} -> fred@hungryhub.com | S39: 45888 | T39: 0.52083333 | U39: 3 | V39: Booked | W39: 574749961032826970 | X39: 7850140 | Y39: 45905 | Z39: {=if(iferror(INDEX(Posts[Username],MATCH(C39&G39,Posts[Username]&Posts[Restaurant Name],0)),"")=C39,"Posted","")} -> Posted | AA39: Guillaume
B40: HH-INROA | C40: roadtrippers.asia | D40: 51300 | E40: Singapore | F40: Tiktok.com/@roadtrippers.asia | G40: Bar Cicheti | H40: {=XLOOKUP(G40,'Restaurant DB All'!B:B,'Restaurant DB All'!A:A)} -> 5343 | I40: {=XLOOKUP(G40,'Restaurant DB'!B:B,'Restaurant DB'!N:N)} -> Italian | J40: Party Pack | K40: 76 | L40: 3-course set dinner menu | M40: None | N40: August Campaing Tiktok https://www.tiktok.com/@roadtrippers.asia IG https://www.instagram.com/eatwithandrewchan Facebook https://www.facebook.com/@roadtrippers.asia Lemon8 https://www.lemon8-app.com/@roadtrippers.asia Xiao Hong Shu https://www.xiaohongshu.com/user/profile/66b9854e000000001d020eb8 Youtube https://youtube.com/@roadtrippers-asia | O40: 7593.87 | R40: {=XLOOKUP(G40,'Restaurant DB'!B:B,'Restaurant DB'!I:I)} -> fred@hungryhub.com | S40: 45888 | T40: 0.79166667 | U40: 3 | V40: Booked | X40: 7813043 | Y40: 45898 | Z40: {=if(iferror(INDEX(Posts[Username],MATCH(C40&G40,Posts[Username]&Posts[Restaurant Name],0)),"")=C40,"Posted","")} -> Posted | AA40: Guillaume
...

Sheet Oct Challenge
B2: KOL username | C2: In Charge | D2: Contacted | E2: Num Reviews | F2: Price per content | G2: Total price | H2: Allergies | I2: Extra Free post
B3: vincas_kitchen | C3: Gui | D3: Contacted/Accepted | E3: 3 | I3: waiting
B4: roadtripper.asia. | C4: Gui | D4: Contacted/Accepted | E4: 4 | I4: 2
B5: 8Foodlab | C5: Gui | D5: Contacted/Accepted | E5: 4
B6: Ieatishootipost | C6: Gui | D6: Contacted
B7: Onebiteonly | C7: Gui | D7: Contacted
B8: seanchankw | C8: Gui | D8: Contacted
B9: dargoyaki | C9: Gui | D9: Contacted
B10: jae7iew | C10: Gui | D10: Contacted
B11: fred.and.chloe | C11: Lars | D11: Contacted/Accepted | E11: 1 | F11: 200
B12: Auntyeats | C12: Lars | D12: Contacted/Refused
B13: Brenda Tan | C13: Lars | D13: Contacted/Refused
B14: certifiedfabclub | C14: Lars | D14: Contacted/Refused
B15: Aikenchia | C15: Lars | D15: Contacted/Refused
B16: Jason.explores | C16: Lars | D16: Contacted/Refused
B17: Lucy.rezel | C17: Lars | D17: Contacted/Accepted | E17: 4 | F17: 200 | G17: 800
B18: Rontreechan | C18: Lars | D18: Contacted/Accepted | E18: 3 | F18: 133 | G18: 400
B19: Amelia_singapore | C19: Lars | D19: Contacted/Ghosted
B20: Fir_foodie | C20: Lars | D20: Contacted/Ghosted
B21: Chiaraang | C21: Lars | D21: Contacted/Ghosted
B22: sakshi_reliving | C22: Lars | D22: Contacted/November
B23: rebeccaeatbook | C23: Lars | D23: Contacted/Accepted | E23: 3 | F23: 100 | G23: 300
B24: VannyTelly | C24: Lars | D24: Contacted/Accepted | E24: 1 | F24: 150 | G24: 150
B25: Lutonikuyalevi | C25: Lars | D25: Contacted/November
B26: Makoeats | C26: Lars | D26: Contacted/Refused
B27: Therantingpanda | C27: Lars | D27: Contacted/Refused
B28: the.sg.nomad | C28: Lars | D28: Contacted/Refused
B29: Myfoodiegallerysg | C29: Tong | D29: Contacted/Accepted | E29: 3 | F29: 300 | G29: 900
B30: eatingjourney | C30: Tong | D30: Contacted/Accepted | F30: 0 | G30: 0
B31: Bigjohnjiak | C31: Tong | D31: Contacted
B32: Goofytwocooks | C32: Tong | D32: Accepted | F32: 250
B33: Foody_flyers | C33: Tong | D33: Refused
B34: Parttimefoodblogger | C34: Tong | D34: ongoing collabs
B35: livewithxiaojie | C35: Tong | D35: Accepted | E35: 2 | F35: 200 | G35: 400
B36: ray_yee | C36: Tong | D36: Accepted
B37: eat_play_lifestyle | C37: Tong | D37: Contacted | F37: 200
B38: Foodkakis | C38: Tong | D38: Accepted | E38: 3 | F38: 120 | G38: 360
B39: eileen_eats_alot | C39: Tong | D39: Contacted | E39: 3 | F39: 200 | G39: 600
B40: Yong Wei Kai | C40: Tong | D40: Contacted
B41: jeethehungrytraveler | C41: Tong | D41: Accepted | F41: 0 | G41: 0
...

Sheet Booking MY
B1: KOL_ID | C1: Username | D1: Followers | E1: Country | F1: Social media URL | G1: Restaurant name | H1: Restaurant ID | I1: Cuisine Type | J1: Package Type | K1: Package price | L1: Package Name | M1: Allergies | N1: Comments | O1: Fee per content | P1: Column 15 | Q1: Column 16 | R1: Column 17 | S1: Target Date | T1: Target time | U1: No people | V1: Sales Check | W1: Line_thread_id | X1: Booking ID | Y1: Target post date | Z1: Post details | AA1: Notes | AB1: index
B2: HH-TESTING | C2: TESTING | D2: 12345 | E2: Test city | F2: ig.com/testing | G2: tesitng restaurant | H2: {=XLOOKUP(G2,'Restaurant DB All'!B:B,'Restaurant DB All'!A:A)} -> #N/A | I2: {=XLOOKUP(G2,'Restaurant DB'!B:B,'Restaurant DB'!N:N)} -> #N/A | J2: Party Pack | K2: 1234 | L2: Testing menu | M2: Testing alergies | N2: Test comments | O2: 12345 | P2: FALSE | R2: {=XLOOKUP(G2,'Restaurant DB'!B:B,'Restaurant DB'!I:I)} -> #N/A | S2: 33156 | T2: 0.75 | U2: 20 | V2: Asked Guillaume | W2: 588528281180176784
B3: HH-TESTING | H3: {=XLOOKUP(G3,'Restaurant DB All'!B:B,'Restaurant DB All'!A:A)} -> #N/A | I3: {=XLOOKUP(G3,'Restaurant DB'!B:B,'Restaurant DB'!N:N)} -> #N/A | P3: FALSE | R3: {=XLOOKUP(G3,'Restaurant DB'!B:B,'Restaurant DB'!I:I)} -> #N/A | W3: 588528294350291663
B4: HH-TESTING | H4: {=XLOOKUP(G4,'Restaurant DB All'!B:B,'Restaurant DB All'!A:A)} -> #N/A | I4: {=XLOOKUP(G4,'Restaurant DB'!B:B,'Restaurant DB'!N:N)} -> #N/A | P4: FALSE | R4: {=XLOOKUP(G4,'Restaurant DB'!B:B,'Restaurant DB'!I:I)} -> #N/A | W4: 588528289937883222
B5: HH-TESTING | H5: {=XLOOKUP(G5,'Restaurant DB All'!B:B,'Restaurant DB All'!A:A)} -> #N/A | I5: {=XLOOKUP(G5,'Restaurant DB'!B:B,'Restaurant DB'!N:N)} -> #N/A | P5: FALSE | R5: {=XLOOKUP(G5,'Restaurant DB'!B:B,'Restaurant DB'!I:I)} -> #N/A | W5: 588528285491921411
B6: {=XLOOKUP(C6,'KOL database'!$C$2:$C$869,'KOL database'!$B$2:$B$869)} -> #REF! | H6: {=XLOOKUP(G6,'Restaurant DB All'!B:B,'Restaurant DB All'!A:A)} -> #N/A | I6: {=XLOOKUP(G6,'Restaurant DB'!B:B,'Restaurant DB'!N:N)} -> #N/A | Q6: Approved | R6: {=XLOOKUP(G6,'Restaurant DB'!B:B,'Restaurant DB'!I:I)} -> #N/A
B7: HH-SGMEY | H7: {=XLOOKUP(G7,'Restaurant DB All'!B:B,'Restaurant DB All'!A:A)} -> #N/A | I7: {=XLOOKUP(G7,'Restaurant DB'!B:B,'Restaurant DB'!N:N)} -> #N/A | R7: {=XLOOKUP(G7,'Restaurant DB'!B:B,'Restaurant DB'!I:I)} -> #N/A

Sheet Posts
B1: KOL_ID | C1: Username | D1: Price per post | E1: Country | F1: Restaurant Code | G1: Restaurant Name | H1: Cuisine Type | I1: Social Media | J1: Social media URL | K1: Booking Date | L1: Booking ID | M1: Boost Code | N1: Post Type | O1: Post Date | P1: Post URL | Q1: D+1 | R1: Views | S1: Comments | T1: Likes | U1: D+5 | V1: Views (+5) | W1: Comments (+5) | X1: Likes (+5) | Y1: D+10 | Z1: Views (+10 | AA1: Comments (+10) | AB1: Likes (+10) | AC1: growth rate | AD1: Conv Rate | AE1: CPM | AF1: Content | AG1: Hook (First 5 Seconds) | AH1: Transcript | AI1: views (latest total)
B2: HH-IN36Y | C2: 365days2play | E2: Bangkok | F2: 1893 | G2: Sirimahannop Asiatique The Riverfront | H2: Thai-European | I2: Instagram | J2: Instagram.com/365days2play | L2: Paid | N2: Video | O2: 45527 | P2: https://www.instagram.com/p/C_AmcP_SZxO/ | Q2: 45839 | R2: 1713 | S2: 18 | T2: -1 | U2: =O2+5 -> 45532 | Y2: 45852 | Z2: 1723 | AA2: 18 | AB2: -1 | AC2: =IFERROR((Z2-R2)/R2,"") -> 0.0058377116 | AD2: =(AA2+AB2)/Z2 -> 0.0098665119 | AE2: =iferror(INDIRECT("D"&ROW()) / INDIRECT("AI"&ROW()) * 1000,0) -> 0 | AG2: Unique things to do aboard a ship, XX cuisines (AI and text) | AI2: =iferror(IFS(Z2>1,Z2,V2>1,V2,R2>1,R2),0) -> 1723
